Workbook

Sheet FRV_Scope
A1: report_id | B1: CAP_NR | C1: Capability | D1: SABI_1 | E1: SABI_2 | F1: EDWH_1 | G1: EDWH_2 | H1: EDWH_3 | I1: EDWH_4 | J1: OU | K1: Directie | L1: Start | M1: End
A2: RAP10033 | B2: 24 | C2: CAP - 24. data & analytics | J2: =IFERROR(VLOOKUP(A2,Directie!$A:$B,2,FALSE),"") -> CLP | K2: =IFERROR(VLOOKUP(A2,Directie!$A:$C,3,FALSE),"") -> SC | L2: 46174 | M2: 46569
A3: RAP10033 | B3: 16 | C3: CAP - 16. direct purchasing | D3: Ivan Zelic | E3: Veera Raghavi Anusha Kakarlapudi | F3: Alan Eykmans | J3: =IFERROR(VLOOKUP(A3,Directie!$A:$B,2,FALSE),"") -> CLP | K3: =IFERROR(VLOOKUP(A3,Directie!$A:$C,3,FALSE),"") -> SC | L3: 46174 | M3: 46569
A4: RAP10033 | B4: 44 | C4: CAP - 44. Store Sales Food | J4: =IFERROR(VLOOKUP(A4,Directie!$A:$B,2,FALSE),"") -> CLP | K4: =IFERROR(VLOOKUP(A4,Directie!$A:$C,3,FALSE),"") -> SC | L4: 46174 | M4: 46569
A5: RAP10033 | B5: 40 | C5: CAP - 40. Retail Product Information | F5: Alan Eykmans | J5: =IFERROR(VLOOKUP(A5,Directie!$A:$B,2,FALSE),"") -> CLP | K5: =IFERROR(VLOOKUP(A5,Directie!$A:$C,3,FALSE),"") -> SC | L5: 46174 | M5: 46569
A6: RAP10033 | B6: 31 | C6: CAP - 31. Infrastructure | D6: Stefan Van Theemsche | F6: Naga Venkata Vamshi Krishna Rao Kanaparthi | J6: =IFERROR(VLOOKUP(A6,Directie!$A:$B,2,FALSE),"") -> CLP | K6: =IFERROR(VLOOKUP(A6,Directie!$A:$C,3,FALSE),"") -> SC | L6: 46174 | M6: 46569
A7: RAP10033 | B7: 71 | C7: CAP - 71. B2C sales food | D7: Christiaan Fosselle | J7: =IFERROR(VLOOKUP(A7,Directie!$A:$B,2,FALSE),"") -> CLP | K7: =IFERROR(VLOOKUP(A7,Directie!$A:$C,3,FALSE),"") -> SC | L7: 46174 | M7: 46569
A8: RAP10034 | B8: 24 | C8: CAP - 24. data & analytics | J8: =IFERROR(VLOOKUP(A8,Directie!$A:$B,2,FALSE),"") -> CLP | K8: =IFERROR(VLOOKUP(A8,Directie!$A:$C,3,FALSE),"") -> SC | L8: 46174 | M8: 46569
A9: RAP10034 | B9: 16 | C9: CAP - 16. direct purchasing | D9: Ivan Zelic | E9: Veera Raghavi Anusha Kakarlapudi | F9: Alan Eykmans | J9: =IFERROR(VLOOKUP(A9,Directie!$A:$B,2,FALSE),"") -> CLP | K9: =IFERROR(VLOOKUP(A9,Directie!$A:$C,3,FALSE),"") -> SC | L9: 46174 | M9: 46569
A10: RAP10034 | B10: 44 | C10: CAP - 44. Store Sales Food | J10: =IFERROR(VLOOKUP(A10,Directie!$A:$B,2,FALSE),"") -> CLP | K10: =IFERROR(VLOOKUP(A10,Directie!$A:$C,3,FALSE),"") -> SC | L10: 46174 | M10: 46569
A11: RAP10034 | B11: 40 | C11: CAP - 40. Retail Product Information | F11: Alan Eykmans | J11: =IFERROR(VLOOKUP(A11,Directie!$A:$B,2,FALSE),"") -> CLP | K11: =IFERROR(VLOOKUP(A11,Directie!$A:$C,3,FALSE),"") -> SC | L11: 46174 | M11: 46569
A12: RAP10034 | B12: 71 | C12: CAP - 71. B2C sales food | D12: Christiaan Fosselle | J12: =IFERROR(VLOOKUP(A12,Directie!$A:$B,2,FALSE),"") -> CLP | K12: =IFERROR(VLOOKUP(A12,Directie!$A:$C,3,FALSE),"") -> SC | L12: 46174 | M12: 46569
A13: RAP10073 | B13: 24 | C13: CAP - 24. data & analytics | J13: =IFERROR(VLOOKUP(A13,Directie!$A:$B,2,FALSE),"") -> CLP | K13: =IFERROR(VLOOKUP(A13,Directie!$A:$C,3,FALSE),"") -> Verkoop | L13: 46174 | M13: 46419
A14: RAP10073 | B14: 47 | C14: CAP - 47. supply chain food | D14: Mustapha Guilmi | E14: Neelam Swamy | F14: Naga Venkata Vamshi Krishna Rao Kanaparthi | G14: SriHarsha Siddam | J14: =IFERROR(VLOOKUP(A14,Directie!$A:$B,2,FALSE),"") -> CLP | K14: =IFERROR(VLOOKUP(A14,Directie!$A:$C,3,FALSE),"") -> Verkoop | L14: 46174 | M14: 46419
A15: RAP10073 | B15: 30 | C15: CAP - 30. it | D15: Nithish Srivathsava Chittampally | E15: Stefan Van Theemsche | J15: =IFERROR(VLOOKUP(A15,Directie!$A:$B,2,FALSE),"") -> CLP | K15: =IFERROR(VLOOKUP(A15,Directie!$A:$C,3,FALSE),"") -> Verkoop | L15: 46174 | M15: 46419
A16: RAP10073 | B16: 44 | C16: CAP - 44. Store Sales Food | J16: =IFERROR(VLOOKUP(A16,Directie!$A:$B,2,FALSE),"") -> CLP | K16: =IFERROR(VLOOKUP(A16,Directie!$A:$C,3,FALSE),"") -> Verkoop | L16: 46174 | M16: 46419
A17: RAP10073 | B17: 40 | C17: CAP - 40. Retail Product Information | F17: Alan Eykmans | J17: =IFERROR(VLOOKUP(A17,Directie!$A:$B,2,FALSE),"") -> CLP | K17: =IFERROR(VLOOKUP(A17,Directie!$A:$C,3,FALSE),"") -> Verkoop | L17: 46174 | M17: 46419
A18: RAP1033 | B18: 24 | C18: CAP - 24. data & analytics | J18: =IFERROR(VLOOKUP(A18,Directie!$A:$B,2,FALSE),"") -> CLP | K18: =IFERROR(VLOOKUP(A18,Directie!$A:$C,3,FALSE),"") -> SC | L18: 46174 | M18: 46569
A19: RAP1033 | B19: 47 | C19: CAP - 47. supply chain food | D19: Mustapha Guilmi | E19: Neelam Swamy | F19: Naga Venkata Vamshi Krishna Rao Kanaparthi | G19: SriHarsha Siddam | J19: =IFERROR(VLOOKUP(A19,Directie!$A:$B,2,FALSE),"") -> CLP | K19: =IFERROR(VLOOKUP(A19,Directie!$A:$C,3,FALSE),"") -> SC | L19: 46174 | M19: 46569
A20: RAP1036 | J20: =IFERROR(VLOOKUP(A20,Directie!$A:$B,2,FALSE),"") -> CLP | K20: =IFERROR(VLOOKUP(A20,Directie!$A:$C,3,FALSE),"") -> SC | L20: 46174 | M20: 46569
A21: RAP1036 | B21: 47 | C21: CAP - 47. supply chain food | D21: Mustapha Guilmi | E21: Neelam Swamy | F21: Naga Venkata Vamshi Krishna Rao Kanaparthi | G21: SriHarsha Siddam | J21: =IFERROR(VLOOKUP(A21,Directie!$A:$B,2,FALSE),"") -> CLP | K21: =IFERROR(VLOOKUP(A21,Directie!$A:$C,3,FALSE),"") -> SC | L21: 46174 | M21: 46569
A22: RAP1036 | B22: 40 | C22: CAP - 40. Retail Product Information | F22: Alan Eykmans | J22: =IFERROR(VLOOKUP(A22,Directie!$A:$B,2,FALSE),"") -> CLP | K22: =IFERROR(VLOOKUP(A22,Directie!$A:$C,3,FALSE),"") -> SC | L22: 46174 | M22: 46569
A23: RAP10413 | B23: 44 | C23: CAP - 44. Store Sales Food | J23: =IFERROR(VLOOKUP(A23,Directie!$A:$B,2,FALSE),"") -> BIO | K23: =IFERROR(VLOOKUP(A23,Directie!$A:$C,3,FALSE),"") -> CO | L23: 46327 | M23: 46600
A24: RAP10413 | B24: 31 | C24: CAP - 31. Infrastructure | D24: Stefan Van Theemsche | F24: Naga Venkata Vamshi Krishna Rao Kanaparthi | J24: =IFERROR(VLOOKUP(A24,Directie!$A:$B,2,FALSE),"") -> BIO | K24: =IFERROR(VLOOKUP(A24,Directie!$A:$C,3,FALSE),"") -> CO | L24: 46327 | M24: 46600
A25: RAP10413 | B25: 37 | C25: CAP - 37. co-worker | D25: Swetha Kotturi | E25: Stefan Van Theemsche | J25: =IFERROR(VLOOKUP(A25,Directie!$A:$B,2,FALSE),"") -> BIO | K25: =IFERROR(VLOOKUP(A25,Directie!$A:$C,3,FALSE),"") -> CO | L25: 46327 | M25: 46600
A26: RAP10553 | B26: 32 | C26: CAP - 32. finance | D26: Nithish Srivathsava Chittampally | E26: Stefan Van Theemsche | J26: =IFERROR(VLOOKUP(A26,Directie!$A:$B,2,FALSE),"") -> CLP | K26: =IFERROR(VLOOKUP(A26,Directie!$A:$C,3,FALSE),"") -> Verkoop | L26: 46174 | M26: 46419
A27: RAP10553 | B27: 24 | C27: CAP - 24. data & analytics | J27: =IFERROR(VLOOKUP(A27,Directie!$A:$B,2,FALSE),"") -> CLP | K27: =IFERROR(VLOOKUP(A27,Directie!$A:$C,3,FALSE),"") -> Verkoop | L27: 46174 | M27: 46419
A28: RAP10553 | B28: 16 | C28: CAP - 16. direct purchasing | D28: Ivan Zelic | E28: Veera Raghavi Anusha Kakarlapudi | F28: Alan Eykmans | J28: =IFERROR(VLOOKUP(A28,Directie!$A:$B,2,FALSE),"") -> CLP | K28: =IFERROR(VLOOKUP(A28,Directie!$A:$C,3,FALSE),"") -> Verkoop | L28: 46174 | M28: 46419
A29: RAP10553 | B29: 18 | C29: CAP - 18. customer | D29: Dimitri Vanlinthout | F29: Dimitri Vanlinthout | G29: Kevin Kollin Mathew | H29: Ajay Mannepalli | I29: Dona Eliza Joseph | J29: =IFERROR(VLOOKUP(A29,Directie!$A:$B,2,FALSE),"") -> CLP | K29: =IFERROR(VLOOKUP(A29,Directie!$A:$C,3,FALSE),"") -> Verkoop | L29: 46174 | M29: 46419
A30: RAP10553 | B30: 44 | C30: CAP - 44. Store Sales Food | J30: =IFERROR(VLOOKUP(A30,Directie!$A:$B,2,FALSE),"") -> CLP | K30: =IFERROR(VLOOKUP(A30,Directie!$A:$C,3,FALSE),"") -> Verkoop | L30: 46174 | M30: 46419
A31: RAP10553 | B31: 40 | C31: CAP - 40. Retail Product Information | F31: Alan Eykmans | J31: =IFERROR(VLOOKUP(A31,Directie!$A:$B,2,FALSE),"") -> CLP | K31: =IFERROR(VLOOKUP(A31,Directie!$A:$C,3,FALSE),"") -> Verkoop | L31: 46174 | M31: 46419
A32: RAP10553 | B32: 71 | C32: CAP - 71. B2C sales food | D32: Christiaan Fosselle | J32: =IFERROR(VLOOKUP(A32,Directie!$A:$B,2,FALSE),"") -> CLP | K32: =IFERROR(VLOOKUP(A32,Directie!$A:$C,3,FALSE),"") -> Verkoop | L32: 46174 | M32: 46419
A33: RAP1091 | B33: 24 | C33: CAP - 24. data & analytics | J33: =IFERROR(VLOOKUP(A33,Directie!$A:$B,2,FALSE),"") -> CLP | K33: =IFERROR(VLOOKUP(A33,Directie!$A:$C,3,FALSE),"") -> SC | L33: 46174 | M33: 46569
A34: RAP1091 | B34: 16 | C34: CAP - 16. direct purchasing | D34: Ivan Zelic | E34: Veera Raghavi Anusha Kakarlapudi | F34: Alan Eykmans | J34: =IFERROR(VLOOKUP(A34,Directie!$A:$B,2,FALSE),"") -> CLP | K34: =IFERROR(VLOOKUP(A34,Directie!$A:$C,3,FALSE),"") -> SC | L34: 46174 | M34: 46569
A35: RAP1091 | B35: 47 | C35: CAP - 47. supply chain food | D35: Mustapha Guilmi | E35: Neelam Swamy | F35: Naga Venkata Vamshi Krishna Rao Kanaparthi | G35: SriHarsha Siddam | J35: =IFERROR(VLOOKUP(A35,Directie!$A:$B,2,FALSE),"") -> CLP | K35: =IFERROR(VLOOKUP(A35,Directie!$A:$C,3,FALSE),"") -> SC | L35: 46174 | M35: 46569
A36: RAP1091 | B36: 18 | C36: CAP - 18. customer | D36: Dimitri Vanlinthout | F36: Dimitri Vanlinthout | G36: Kevin Kollin Mathew | H36: Ajay Mannepalli | I36: Dona Eliza Joseph | J36: =IFERROR(VLOOKUP(A36,Directie!$A:$B,2,FALSE),"") -> CLP | K36: =IFERROR(VLOOKUP(A36,Directie!$A:$C,3,FALSE),"") -> SC | L36: 46174 | M36: 46569
A37: RAP1091 | B37: 40 | C37: CAP - 40. Retail Product Information | F37: Alan Eykmans | J37: =IFERROR(VLOOKUP(A37,Directie!$A:$B,2,FALSE),"") -> CLP | K37: =IFERROR(VLOOKUP(A37,Directie!$A:$C,3,FALSE),"") -> SC | L37: 46174 | M37: 46569
A38: RAP10915 | B38: 24 | C38: CAP - 24. data & analytics | J38: =IFERROR(VLOOKUP(A38,Directie!$A:$B,2,FALSE),"") -> CLP | K38: =IFERROR(VLOOKUP(A38,Directie!$A:$C,3,FALSE),"") -> SC | L38: 46174 | M38: 46569
A39: RAP10915 | B39: 47 | C39: CAP - 47. supply chain food | D39: Mustapha Guilmi | E39: Neelam Swamy | F39: Naga Venkata Vamshi Krishna Rao Kanaparthi | G39: SriHarsha Siddam | J39: =IFERROR(VLOOKUP(A39,Directie!$A:$B,2,FALSE),"") -> CLP | K39: =IFERROR(VLOOKUP(A39,Directie!$A:$C,3,FALSE),"") -> SC | L39: 46174 | M39: 46569
A40: RAP10915 | B40: 37 | C40: CAP - 37. co-worker | D40: Swetha Kotturi | E40: Stefan Van Theemsche | J40: =IFERROR(VLOOKUP(A40,Directie!$A:$B,2,FALSE),"") -> CLP | K40: =IFERROR(VLOOKUP(A40,Directie!$A:$C,3,FALSE),"") -> SC | L40: 46174 | M40: 46569
...

Sheet Directie
A1: RAP | B1: OU | C1: Directie
A2: RAP10073 | B2: CLP | C2: Verkoop
A3: RAP18073 | B3: CLP | C3: Verkoop
A4: RAP18113 | B4: CLP | C4: Verkoop
A5: RAP18993 | B5: CLP | C5: Verkoop
A6: RAP21393 | B6: CLP | C6: Verkoop
A7: RAP21413 | B7: CLP | C7: Verkoop
A8: RAP23722 | B8: CLP | C8: Verkoop
A9: RAP24490 | B9: CLP | C9: Verkoop
A10: RAP2560 | B10: CLP | C10: Verkoop
A11: RAP25652 | B11: CLP | C11: Verkoop
A12: RAP25653 | B12: CLP | C12: Verkoop
... A2979: RAP32661 | B2979: 42. retail price food | C2979: CO
A2980: RAP32795 | B2980: Retail Services | C2980: CO | D2980: ! Retail Services is indication: was not filled in in orginal list
A2981: RAP32801 | B2981: 42. retail price food | C2981: CO
A2982: RAP32802 | B2982: Retail Services | C2982: CO | D2982: ! Retail Services is indication: was not filled in in orginal list
A2983: RAP33646 | B2983: 42. retail price food | C2983: CO
A2984: RAP33963 | B2984: Retail Services | C2984: CO
A2985: RAP33965 | B2985: Retail Services | C2985: CO
A2986: RAP33966 | B2986: Retail Services | C2986: CO
A2987: RAP33967 | B2987: Retail Services | C2987: CO
A2988: RAP30925 | B2988: 42. retail price food | C2988: CO
A2989: RAP29847 | B2989: 42. retail price food | C2989: CO
A2990: RAP23610 | B2990: 42. retail price food | C2990: CO
A2991: RAP24204 | B2991: 42. retail price food | C2991: CO
A2992: RAP24591 | B2992: 42. retail price food | C2992: CO
A2993: RAP24826 | B2993: 42. retail price food | C2993: CO
A2994: RAP25041 | B2994: 42. retail price food | C2994: CO
... A2996: RAP32101 | B2996: 42. retail price food | C2996: CO
A2997: RAP30500 | B2997: Retail Services | C2997: CO | D2997: ! Retail Services is indication: was not filled in in orginal list
A2998: RAP32806 | B2998: 42. retail price food | C2998: CO
A2999: RAP34029 | B2999: 42. retail price food | C2999: CO
A3000: RAP25852 | B3000: Retail Services | C3000: CO
A3001: RAP25885 | B3001: 42. retail price food | C3001: CO
A3002: RAP32273 | B3002: 42. retail price food | C3002: CO
A3003: RAP32567 | B3003: 42. retail price food | C3003: CO
A3004: RAP28082 | B3004: 42. retail price food | C3004: CO
A3005: RAP32976 | B3005: 42. retail price food | C3005: CO
A3006: RAP28883 | B3006: 42. retail price food | C3006: CO
A3007: RAP28957 | B3007: 42. retail price food | C3007: CO
...

Sheet Caps per FRV iRap
A1: RAP10033 | B1: {=_xlfn.TEXTJOIN(", ", TRUE, IF('Caps per iRap'!$A$2:$A$19587=A1, 'Caps per iRap'!$B$2:$B$19587, ""))} -> 24, 16, 44, 40, 31, 71
A2: RAP10034 | B2: {=_xlfn.TEXTJOIN(", ", TRUE, IF('Caps per iRap'!$A$2:$A$19587=A2, 'Caps per iRap'!$B$2:$B$19587, ""))} -> 24, 16, 44, 40, 71
A3: RAP10073 | B3: {=_xlfn.TEXTJOIN(", ", TRUE, IF('Caps per iRap'!$A$2:$A$19587=A3, 'Caps per iRap'!$B$2:$B$19587, ""))} -> 24, 47, 30, 44, 40
A4: RAP1033 | B4: {=_xlfn.TEXTJOIN(", ", TRUE, IF('Caps per iRap'!$A$2:$A$19587=A4, 'Caps per iRap'!$B$2:$B$19587, ""))} -> 24, 47
A5: RAP1036 | B5: {=_xlfn.TEXTJOIN(", ", TRUE, IF('Caps per iRap'!$A$2:$A$19587=A5, 'Caps per iRap'!$B$2:$B$19587, ""))} -> 0, 47, 40
A6: RAP10413 | B6: {=_xlfn.TEXTJOIN(", ", TRUE, IF('Caps per iRap'!$A$2:$A$19587=A6, 'Caps per iRap'!$B$2:$B$19587, ""))} -> 44, 31, 37
A7: RAP10553 | B7: {=_xlfn.TEXTJOIN(", ", TRUE, IF('Caps per iRap'!$A$2:$A$19587=A7, 'Caps per iRap'!$B$2:$B$19587, ""))} -> 32, 24, 16, 18, 44, 40, 71
A8: RAP1091 | B8: {=_xlfn.TEXTJOIN(", ", TRUE, IF('Caps per iRap'!$A$2:$A$19587=A8, 'Caps per iRap'!$B$2:$B$19587, ""))} -> 24, 16, 47, 18, 40
A9: RAP10915 | B9: {=_xlfn.TEXTJOIN(", ", TRUE, IF('Caps per iRap'!$A$2:$A$19587=A9, 'Caps per iRap'!$B$2:$B$19587, ""))} -> 24, 47, 37
A10: RAP11014 | B10: {=_xlfn.TEXTJOIN(", ", TRUE, IF('Caps per iRap'!$A$2:$A$19587=A10, 'Caps per iRap'!$B$2:$B$19587, ""))} -> 0
A11: RAP11093 | B11: {=_xlfn.TEXTJOIN(", ", TRUE, IF('Caps per iRap'!$A$2:$A$19587=A11, 'Caps per iRap'!$B$2:$B$19587, ""))} -> 32, 18, 44, 31, 37
A12: RAP1164 | B12: {=_xlfn.TEXTJOIN(", ", TRUE, IF('Caps per iRap'!$A$2:$A$19587=A12, 'Caps per iRap'!$B$2:$B$19587, ""))} -> 24, 47, 40
... A2451: RAP6304 | B2451: {=_xlfn.TEXTJOIN(", ", TRUE, IF('Caps per iRap'!$A$2:$A$19587=A2451, 'Caps per iRap'!$B$2:$B$19587, ""))} -> 42, 30, 44, 40
A2452: RAP32686 | B2452: 24, 40, 71
A2453: RAP32711 | B2453: 0, 24, 44, 40, 71

Sheet Caps per iRap
A1: report_id | B1: CAP_NR
A2: RAP4932 | B2: 24
A3: RAP4932 | B3: 47
A4: RAP4932 | B4: 44
A5: RAP26851
A6: RAP26851 | B6: 16
A7: RAP26851 | B7: 47
A8: RAP26851 | B8: 44
A9: RAP26851 | B9: 40
A10: RAP26851 | B10: 71
A11: RAP26851 | B11: 20
A12: RAP3736 | B12: 24
A13: RAP3736 | B13: 47
A14: RAP3736 | B14: 40
A15: RAP3736 | B15: 37
A16: RAP7602 | B16: 32
A17: RAP7602 | B17: 24
... A36: RAP27288 | B36: 28
A37: RAP4820
A38: RAP4820 | B38: 30
A39: RAP28491 | B39: 24
A40: RAP28491 | B40: 30
A41: RAP28491 | B41: 31
A42: RAP26790 | B42: 24
A43: RAP26790 | B43: 30
A44: RAP26790 | B44: 18
A45: RAP26790 | B45: 51
A46: RAP26790 | B46: 44
A47: RAP26790 | B47: 40
A48: RAP26790 | B48: 31
A49: RAP30680
A50: RAP30680 | B50: 24
A51: RAP30680 | B51: 47
A52: RAP30680 | B52: 44
A53: RAP30680 | B53: 40
A54: RAP30680 | B54: 31
A55: RAP30680 | B55: 71
A56: RAP31322 | B56: 32
A57: RAP31322 | B57: 24
A58: RAP31322 | B58: 44
...

Sheet SABI_List
A1: CAPABILITY | B1: SABI_1 | C1: SABI_2 | D1: EDWH_1 | E1: EDWH_2 | F1: EDWH_3 | G1: EDWH_4
A2: CAP - 00. identity & culture
A3: CAP - 01. strategy definition
A4: CAP - 02. resource planning
A5: CAP - 03. risk
A6: CAP - 04. market watch
A7: CAP - 05. performance watch
A8: CAP - 06. business change
A9: CAP - 07. real estate | B9: Stefan Van Theemsche | D9: Naga Venkata Vamshi Krishna Rao Kanaparthi
A10: CAP - 08. sustainability
A11: CAP - 09. R&D & innovation
A12: CAP - 10. digitalisation
A13: CAP - 11. stakeholder relations governance & reputation
A14: CAP - 12. communication & collaboration
A15: CAP - 14. marketing promotion | B15: Dimitri Vanlinthout | D15: Dimitri Vanlinthout | E15: Kevin Kollin Mathew | F15: Ajay Mannepalli | G15: Dona Eliza Joseph
A16: CAP - 15. contact center | B16: Dimitri Vanlinthout | D16: Dimitri Vanlinthout
A17: CAP - 16. direct purchasing | B17: Ivan Zelic | C17: Veera Raghavi Anusha Kakarlapudi | D17: Alan Eykmans
A18: CAP - 17. customer offer | B18: Philippe Du Bois | C18: Vivek Padinhare Veedu
A19: CAP - 18. customer | B19: Dimitri Vanlinthout | D19: Dimitri Vanlinthout | E19: Kevin Kollin Mathew | F19: Ajay Mannepalli | G19: Dona Eliza Joseph
A20: CAP - 20. business partner | B20: Ivan Zelic | C20: Veera Raghavi Anusha Kakarlapudi | D20: Alan Eykmans
A21: CAP - 21. party
A22: CAP - 22. workplace
A23: CAP - 23. integrated knowledge & search
A24: CAP - 24. data & analytics
A25: CAP - 25. indirect purchasing & warehousing | C25: Stefan Van Theemsche | D25: Naga Venkata Vamshi Krishna Rao Kanaparthi
A26: CAP - 26. compliance
A27: CAP - 27. customer payments | B27: Nithish Srivathsava Chittampally | C27: Stefan Van Theemsche
A28: CAP - 28. strategic & tactical planning
A29: CAP - 29. service & process
A30: CAP - 30. it | B30: Nithish Srivathsava Chittampally | C30: Stefan Van Theemsche
A31: CAP - 31. Infrastructure | B31: Stefan Van Theemsche | D31: Naga Venkata Vamshi Krishna Rao Kanaparthi
A32: CAP - 32. finance | B32: Nithish Srivathsava Chittampally | C32: Stefan Van Theemsche
A33: CAP - 35. Partnership & Organisation
A34: CAP - 36. Learning Solutions
A35: CAP - 37. co-worker | B35: Swetha Kotturi | C35: Stefan Van Theemsche
A36: CAP - 39. B2B foodservices | D36: Swapna Sarit Mallick
A37: CAP - 40. Retail Product Information | D37: Alan Eykmans
A38: CAP - 41. Contribution Food
A39: CAP - 42. Retail Price Food | B39: Philippe Du Bois
A40: CAP - 43. Logistic Workforce Food
...

Sheet Sheet1
A3: Row Labels | B3: Count of report_id | D3: Line of business | E3: Count of reports
A4: 0 | B4: 50 | D4: Colruyt Laagste Prijzen | E4: 718
A5: 12. communication & collaboration | B5: 1 | D5: Retail Partners Colruyt Group | E5: 433
A6: 16. direct purchasing | B6: 186 | D6: 42. retail price food | E6: 245
A7: 17. customer offer | B7: 17 | D7: 16. direct purchasing | E7: 186
A8: 18. customer | B8: 4 | D8: OKay | E8: 125
A9: 25. indirect purchasing & warehousing | B9: 4 | D9: #N/A | E9: 100
A10: 32. finance | B10: 12 | D10: CLP Supply Chain | E10: 64
A11: 37. co-worker | B11: 61 | D11: 37. co-worker | E11: 61
A12: 39. B2B foodservice | B12: 13 | D12: Bio-Planet | E12: 60
A13: 40. retail product information | B13: 3 | D13: Collect & Go | E13: 56
A14: 41. contribution food | B14: 30 | D14: Retail Services | E14: 54
A15: 42. retail price food | B15: 245 | D15: blank | E15: 50
A16: 43. logistic workforce food | B16: 6 | D16: Finance | E16: 43
... A50: Grand Total | B50: 2453 | D50: Grand Total | E50: 2453

Sheet Unique Reports
A1: report_id | B1: OU | C1: Directie | D1: Capabilities | E1: Report Name | F1: Line of Business | G1: Report Description (EN) | H1: Report Description (NL)
A2: RAP10033 | B2: CLP | C2: SC | D2: =VLOOKUP(A2,'Caps per FRV iRap'!A:B,2,0) -> 24, 16, 44, 40, 31, 71 | E2: Verkoop fruit groenten artikel code besteller lopende vorige maand | F2: 16. direct purchasing | G2: Confidential | H2: INBOX 26 BO 1M lopende maande en vorige maand cijfers aankopers fruit en groenten per artikel. Omzet, stuks, BW en afval
A3: RAP10034 | B3: CLP | C3: SC | D3: =VLOOKUP(A3,'Caps per FRV iRap'!A:B,2,0) -> 24, 16, 44, 40, 71 | E3: Verkoop fruit groenten artikel code besteller gisteren | F3: 16. direct purchasing | G3: Confidential | H3: INBOX 27 BO 1D gisteren cijfers aankopers per artikel stuks, omzet, BW en afval
A4: RAP10073 | B4: CLP | C4: Verkoop | D4: =VLOOKUP(A4,'Caps per FRV iRap'!A:B,2,0) -> 24, 47, 30, 44, 40 | E4: Artikelen meer dan 100 dagen stock filiaal firma FD VP DV | F4: Colruyt Laagste Prijzen | G4: All items FD, DV and VP with more than 100 days of stock at company and branch level. Available stock, number of branches track, forecast, branch stock | H4: Alle artikelen FD, DV en VP met meer dan 100 dagen stock op firma- en filiaalniveau. Beschikbare stock, aantal filalen volgen, prognose, filiaalstock
A5: RAP1033 | B5: CLP | C5: SC | D5: =VLOOKUP(A5,'Caps per FRV iRap'!A:B,2,0) -> 24, 47 | E5: Lege stockageplaatsen per blok | F5: Colruyt Laagste Prijzen | G5: Confidential | H5: Per blok kunnen de vrije en bezette plaatsen in het magazijn opgevraagd worden.
A6: RAP1036 | B6: CLP | C6: SC | D6: =VLOOKUP(A6,'Caps per FRV iRap'!A:B,2,0) -> 0, 47, 40 | E6: Onvolledige paletten reserve blok R | F6: Colruyt Laagste Prijzen | G6: Confidential | H6: Dit rapport geeft een overzicht van de paletten die onvolledig zijn Selectie obv blok W of R, stocksoort F of B en soort plaats R of N. Een palet is onvolledig indien aantal SE &lt; U
A7: RAP10413 | B7: BIO | C7: CO | D7: =VLOOKUP(A7,'Caps per FRV iRap'!A:B,2,0) -> 44, 31, 37 | E7: REMOVAL on 01Oct2026_Koppen en voltijdsequivalenten per filiaal | F7: 37. co-worker | G7: Not Applicable | H7: !!Dit rapport verdwijnt op 1 okt 2026!! Link Power BI-rapport in rap10413 'tab Info'. HC en FTE per filiaal. Voor het volledige filiaal als opgesplitst voor BH'en en winkels.
A8: RAP10553 | B8: CLP | C8: Verkoop | D8: =VLOOKUP(A8,'Caps per FRV iRap'!A:B,2,0) -> 32, 24, 16, 18, 44, 40, 71 | E8: Verkopen horecawijnen per prospecteur | F8: Colruyt Laagste Prijzen | G8: Confidential | H8: Weergave van het aantal verkochte wijnen , per referentie , per klant, per maand gekoppeld aan een accountmanager CLP4P.
A9: RAP1091 | B9: CLP | C9: SC | D9: =VLOOKUP(A9,'Caps per FRV iRap'!A:B,2,0) -> 24, 16, 47, 18, 40 | E9: leveringen art leva in pallet | F9: Colruyt Laagste Prijzen | G9: Confidential | H9: geeft het leveringen art leva in pal afhaling
A10: RAP10915 | B10: CLP | C10: SC | D10: =VLOOKUP(A10,'Caps per FRV iRap'!A:B,2,0) -> 24, 47, 37 | E10: overzicht aantal correcties per rondhaler per week | F10: Colruyt Laagste Prijzen | G10: Confidential | H10: overzicht aantal correcties per rondhaler per week
A11: RAP11014 | B11: CLP | C11: SC | D11: =VLOOKUP(A11,'Caps per FRV iRap'!A:B,2,0) -> 0 | E11: Aantal tellingen per afdeling _nultelling facturatie en wekelijkse | F11: Colruyt Laagste Prijzen | G11: Confidential | H11: Dit rapport geeft het aantal tellingen van vandaag per afdeling opgesplitst in nultellingen, tellingen tijdens facturatie en wekelijkse tellingen.
A12: RAP11093 | B12: CLP | C12: Verkoop | D12: =VLOOKUP(A12,'Caps per FRV iRap'!A:B,2,0) -> 32, 18, 44, 31, 37 | E12: Nieuwe factuurklanten binnen branche Horeca die geen Prof klant zijn | F12: Colruyt Laagste Prijzen | G12: Confidential | H12: Nieuwe factuurklanten in Colruytwinkels waarvan vastgesteld werden dat ze in de Horeco aktief zijn. Potentiële klanten voor Prof-tarief
A13: RAP1164 | B13: CLP | C13: SC | D13: =VLOOKUP(A13,'Caps per FRV iRap'!A:B,2,0) -> 24, 47, 40 | E13: art ZBH met datum nieuw 0 | F13: Colruyt Laagste Prijzen | G13: Confidential | H13: geeft de artikel van zelfbedieningsbeenhouwerijen
... A25: RAP1215 | B25: CLP | C25: SC | D25: =VLOOKUP(A25,'Caps per FRV iRap'!A:B,2,0) -> 47 | E25: overzicht ritten vertrokken vanuit magazijn | F25: Colruyt Laagste Prijzen | G25: Confidential | H25: Dit rapport geeft een overzicht van alle ritten vertrokken vanaf een bepaald magazijn
A26: RAP12293 | B26: CLP | C26: SC | D26: =VLOOKUP(A26,'Caps per FRV iRap'!A:B,2,0) | E26: #N/A | F26: #N/A | G26: #N/A | H26: #N/A
A27: RAP1233 | B27: CLP | C27: SC | D27: =VLOOKUP(A27,'Caps per FRV iRap'!A:B,2,0) -> 24, 47 | E27: Ritten voor chauffeur met algemene informatie | F27: Colruyt Laagste Prijzen | G27: Confidential | H27: Dit rapport geeft een overzicht van het dagparcours van een chauffeur met aanduiding van rij- en rusttijden
A28: RAP1237 | B28: CLP | C28: SC | D28: =VLOOKUP(A28,'Caps per FRV iRap'!A:B,2,0) -> 24, 47 | E28: Totaal overzicht retourvracht per magazijn | F28: Colruyt Laagste Prijzen | G28: Confidential | H28: Dit rapport geeft een overzicht van per magazijn over een bepaalde periode van het aantal tpe's die als terugvracht getransporteerd werden naar het betrokken magazijn.
A29: RAP12414 | B29: CLP | C29: Verkoop | D29: =VLOOKUP(A29,'Caps per FRV iRap'!A:B,2,0) -> 32, 24, 18, 44, 71 | E29: Omrekening profkorting kortingpercentage 5 | F29: Colruyt Laagste Prijzen | G29: Confidential | H29: In het rapport wordt de profkorting die een klant binnen een periode kreeg aan een bepaald profkortingpercentage omgerekend alsof deze klant recht had op 5% korting.
A30: RAP1242 | B30: CLP | C30: SC | D30: =VLOOKUP(A30,'Caps per FRV iRap'!A:B,2,0) -> 24, 47 | E30: verdienste specifieke transporteur over periode | F30: Colruyt Laagste Prijzen | G30: Confidential | H30: overzicht van de verdienste van een bepaalde transporteur voor een bepaalde periode.Opgelet: het ingeven van % is niet mogelijk als ingave bij chauffeur prompt
A31: RAP12436 | B31: CLP | C31: Verkoop | D31: =VLOOKUP(A31,'Caps per FRV iRap'!A:B,2,0) -> 0, 24, 18, 44, 71 | E31: Overzicht cbhids meer dan 5 keer herkend dmv extra kaart per regiomgr | F31: Corporate Marketing | G31: Confidential | H31: Overzicht van de cbhids die vorige week meer dan 5 keer herkend werden op eenzelfde dag
A32: RAP1249 | B32: CLP | C32: SC | D32: =VLOOKUP(A32,'Caps per FRV iRap'!A:B,2,0) -> 47 | E32: wie reed met oplegger | F32: Colruyt Laagste Prijzen | G32: Confidential | H32: geeft weer wie binnen een bepaalde periode met de gevraagde oplegger heeft gereden
A33: RAP12515 | B33: CLP | C33: Verkoop | D33: =VLOOKUP(A33,'Caps per FRV iRap'!A:B,2,0) -> 24, 47, 30, 5, 18, 44, 40, 71 | E33: Opvolgen horeca assortiment per maand per filiaal | F33: Colruyt Laagste Prijzen | G33: Confidential | H33: Vertrouwelijk
A34: RAP12517 | B34: CLP | C34: SC | D34: =VLOOKUP(A34,'Caps per FRV iRap'!A:B,2,0) -> 47, 37 | E34: Tussentijden borderels ONLINE | F34: Colruyt Laagste Prijzen | G34: Confidential | H34: De tijd tussen 2 borderels per rondhaler; PROMPTS: rondhaaldatum en rondhaalzones
A35: RAP12595 | B35: CLP | C35: SC | D35: =VLOOKUP(A35,'Caps per FRV iRap'!A:B,2,0) -> 24, 47, 40 | E35: niet getelde artikelen sinds | F35: Colruyt Laagste Prijzen | G35: Confidential | H35: Geeft de artikels per afdeling die niet meer geteld zijn sinds de ingegeven datum. Weergave van laatste telling door stockcontrole en bevoorrader, beschikbare stock en plmg.
A36: RAP1260 | B36: CLP | C36: SC | D36: =VLOOKUP(A36,'Caps per FRV iRap'!A:B,2,0) -> 47, 44, 37 | E36: Opzoeken rondhalers van een borderel NF en CS via bordnr | F36: Colruyt Laagste Prijzen | G36: Confidential | H36: Opzoeken rondhalers van een borderel NF en CS via borderelnummer
A37: RAP128 | B37: CLP | C37: Verkoop | D37: =VLOOKUP(A37,'Caps per FRV iRap'!A:B,2,0) -> 32, 18 | E37: Turnover Promisory Note Customers | F37: Finance | G37: Revenue Promessen | H37: Omzet Promessen
A38: RAP1283 | B38: CLP | C38: SC | D38: =VLOOKUP(A38,'Caps per FRV iRap'!A:B,2,0) -> 24, 47, 40, 37, 43 | E38: Overzicht rondhalers per pickingplaats | F38: 50. B2C e-commerce food | G38: Confidential | H38: Overzicht rondhalers die op een bepaalde plaats rondhaalden in de facturatie van gisteren
... A92: RAP21473 | B92: CLP | C92: AK | D92: =VLOOKUP(A92,'Caps per FRV iRap'!A:B,2,0) -> 32, 16, 30, 40, 20 | E92: Tarieflijst Aankoopdossier | F92: 16. direct purchasing | G92: Confidential | H92: overzicht BTP tarieven lijst per versie aankoopdossier
A93: RAP2151 | B93: OKAY | C93: Verkoop | D93: =VLOOKUP(A93,'Caps per FRV iRap'!A:B,2,0) | E93: #N/A | F93: #N/A | G93: #N/A | H93: #N/A
A94: RAP21613 | B94: OKAY | C94: Verkoop | D94: =VLOOKUP(A94,'Caps per FRV iRap'!A:B,2,0) -> 24, 47, 44, 40, 31, 71 | E94: Okay City Direct opvolging verkoop stock artikel filiaal regiomanager | F94: OKay | G94: Confidential | H94: In deze rapport vind je voor gevraagde artiklel en periode : verkoopcijfers en stock op filiaalniveau.
A95: RAP21973 | B95: CLP | C95: SC | D95: =VLOOKUP(A95,'Caps per FRV iRap'!A:B,2,0) -> 24, 47, 40 | E95: opvolging artikelen met stock zonder afmetingen of gewicht | F95: Colruyt Laagste Prijzen | G95: Confidential | H95: opvolging artikelen met stock zonder afmetingen of gewicht
A96: RAP22884 | B96: CLP | C96: Verkoop | D96: =VLOOKUP(A96,'Caps per FRV iRap'!A:B,2,0) -> 0, 42, 24, 18, 44, 40, 31, 71 | E96: Omrekenen kasticket of factuur met geldige Cprijzen en alle kortingen | F96: Colruyt Laagste Prijzen | G96: Confidential | H96: Om op basis van aankoopdatum, filiaalnr en kasticketnummer, het kasticket te herrekenen naar de Cprijzen zoals van kracht op datum. (meer info in metadata, tab ''Omschrijving'')
A97: RAP22885 | B97: CLP | C97: SC | D97: =VLOOKUP(A97,'Caps per FRV iRap'!A:B,2,0) -> 24, 16, 47, 40 | E97: Artikels per afdeling waar geen bevoorrading op zit sinds een datum | F97: Colruyt Laagste Prijzen | G97: ? | H97: Geeft de artikels waar geen bevoorrading op zit sinds de opgegeven datum. Toont of het artikel geblokkeerd is, moeder/dochter is, de levertermijn, beschikbare en wachtstock.
A98: RAP22892 | B98: CLP | C98: SC | D98: =VLOOKUP(A98,'Caps per FRV iRap'!A:B,2,0) -> 0 | E98: Overzicht lege plaatsen per blok of gang nonfood en collishop | F98: Colruyt Laagste Prijzen | G98: ? | H98: Geeft een overzicht van alle lege plaatsen in een bepaalde blok of gang van de afdelingen nonfood en collishop. Blok is verplicht, gang optioneel.
A99: RAP22904 | B99: CLP | C99: SC | D99: =VLOOKUP(A99,'Caps per FRV iRap'!A:B,2,0) -> 24, 47, 44, 40, 45 | E99: Resultaat simulatie herbevoorrading aantal colli's per magazijn vandaa | F99: Colruyt Laagste Prijzen | G99: ? | H99: ?
A100: RAP22906 | B100: CLP | C100: SC | D100: =VLOOKUP(A100,'Caps per FRV iRap'!A:B,2,0) -> 0, 24, 47, 44, 40 | E100: Overzicht filiaal of en artikel op PARH | F100: 45. sales forecasting food | G100: Confidential | H100: Vertrouwelijk
A101: RAP22947 | B101: CLP | C101: SC | D101: =VLOOKUP(A101,'Caps per FRV iRap'!A:B,2,0) -> 24, 47, 44 | E101: Vullingsgraad transportplanning | F101: Colruyt Laagste Prijzen | G101: Confidential | H101: Rapport geeft gemiddelde vullingsgraad per dag van alle ritten in de automatische planning.
A102: RAP23039 | B102: CLP | C102: SC | D102: =VLOOKUP(A102,'Caps per FRV iRap'!A:B,2,0) -> 24, 16, 18, 40 | E102: controle receptie op leveranciernr | F102: Colruyt Laagste Prijzen | G102: ? | H102: Geeft recepties weer tss bepaalde periode van bepaalde leverancier
A103: RAP23057 | B103: RPCG | C103: RPCG | D103: =VLOOKUP(A103,'Caps per FRV iRap'!A:B,2,0) -> 24, 48 | E103: opzoeken fouten weekrapportage | F103: Retail Partners Colruyt Group | G103: Confidential | H103: opzoeken fouten weekrapportage
A104: RAP23066 | B104: CLP | C104: SC | D104: =VLOOKUP(A104,'Caps per FRV iRap'!A:B,2,0) -> 24, 47, 40 | E104: Palletten te verwerken in circuit voor acirca vandaag per artikel | F104: Colruyt Laagste Prijzen | G104: ? | H104: Geeft aantal palletten bestemd voor circuit voor de facturatie van vandaag per gang, dus zonder de palletbestellingen. Geeft aantal palletplaatsen en plaatsstock van deze ochtend.
...
